Workbook

Sheet ReadMe
B1: European on-demand digital manufacturing: audit workbook
B2: Prepared 14 July 2026. Companion to the Word report. All currency EUR unless noted.
B4: Tabs
B5: Competitor Matrix | C5: Profiles of 27 players: EU asset-heavy, marketplaces, aggregator, Chinese price floor, Polish bureaus, US benchmark.
B6: Pricing Benchmark | C6: Quoted / triangulated prices for 3 reference parts across 10+ providers. Ranges are estimates unless marked FACT.
B7: Model A FDM Farm | C7: CAPEX and unit economics for a 20-30 unit industrial FDM farm in Poland. Editable.
B8: Model B MJF Cell | C8: CAPEX and unit economics for a single HP MJF 5600-class cell. Editable.
B9: Scenario Compare | C9: Side-by-side of the two entry scenarios.
B11: How to use the models
B12: Editable cells | C12: Blue text on yellow fill = assumption you can change. Everything else is a formula and recalculates.
B13: Example edit | C13: On 'Model A FDM Farm', set B5 (machine count) to 30 and B16 (price per machine-hour) to 5.00 to see a higher-price case.
B15: Data quality legend
B16: FACT | C16: From a primary source (filing, registry, company statement, published price page). Source noted in the row.
B17: ESTIMATE | C17: Triangulated from partial data. Reasoning noted.
B18: ASSUMPTION | C18: Modeling judgment, no direct source. Treat as a lever to test.
B19: [STALE] | C19: Data older than January 2025.
B21: Key caveats
B22: Pricing | C22: No live CAD uploads were made. Prices come from published rate cards, provider example quotes, and third-party same-STL benchmarks (All3DP June 2026 and July 2024). Where a provider gates quotes behind an account, that is flagged.
B23: Private companies | C23: German GmbHs use small-company exemptions; most marketplace revenues are estimates.
B24: Models | C24: Steady-state economics. Year-1 ramp factor applies fixed costs to partial revenue. Defaults are calibrated so Model A lands near Weerg's reported ~40 percent EBITDA profile.

Sheet Competitor Matrix
A1: Company | B1: HQ / production | C1: Model | D1: Processes | E1: Instant quote | F1: Lead time (typical) | G1: Pricing position | H1: Revenue (latest known) | I1: Profitability / funding | J1: Confidence | K1: Target segment | L1: Certifications | M1: Defense exposure | N1: Recurring weaknesses | O1: Key source
A2: Weerg | B2: Scorze (Venice), IT; single 6,000 m2 plant | C2: In-house | D2: MJF (28-30x HP 5620), resin, high-temp FFF (PEEK/ULTEM), CNC, laser | E2: Yes, no login | F2: MJF <2 d production + 1-2 d EU ship | G2: Budget-aggressive | H2: EUR 13.6M FY2024 filed; ~EUR 18M 2025 and EUR 25M 2026 target (company) | I2: EUR 1.75M net profit FY2024 (registry); ~40% EBITDA (company claim); self-funded | J2: High (FY24) / Medium (2025) | K2: SME engineers, proto to mid-series | L2: ISO 9001 | M2: Low; no AS9100 | N2: Batch quality inconsistency, tolerance misses, weak exception comms (Trusted Shops). Founder publicly intends to sell (Feb 2026) | O2: reportaziende.it registry FY2024; Industria Italiana 19 Feb 2026
A3: Protolabs (EU factories) | B3: Maple Plain US; EU: Telford UK, Putzbrunn DE | C3: In-house | D3: CNC, injection molding, 3DP (MJF/SLA/SLS/DMLS), sheet | E3: Yes | F3: 1 d express possible | G3: Premium | H3: Europe USD 100.8M FY2025, -7% constant currency; group USD 533.1M | I3: Group net income USD 16.6M FY2025; GAAP gross margin 44.5% | J3: High | K3: Enterprise, regulated industries | L3: ISO 9001, AS9100D, ISO 13485, ITAR (US only) | M3: High in US; ITAR does not extend to EU plants | N3: Expensive at quantity (3-5x cheapest in benchmarks); Europe shrinking | O3: PRLB 10-K FY2025; earnings release 6 Feb 2026
A4: Protolabs Network (ex-Hubs) | B4: Amsterdam NL | C4: Marketplace | D4: CNC, 3DP, sheet, IM via 250+ vetted partners | E4: Yes (98% instant) | F4: From 3 d | G4: Mid | H4: USD 116.2M FY2025, +15.7% | I4: Implied gross margin ~29% (triangulated); being integrated into 'one Protolabs' | J4: High (rev) / Medium (GM) | K4: Price-sensitive overflow | L4: Partner-level | M4: Low in EU | N4: Order consistency varies by partner | O4: PRLB Q4 FY2025 release, 6 Feb 2026
A5: MABS 3D | B5: Brescia, IT | C5: In-house (micro) | D5: FDM, SLS, resin/DLP, 3D scanning | E5: Yes | F5: Same-day quotes | G5: Budget local | H5: Not filed (sole proprietorship); <EUR 0.5M assumed | I5: Unknown | J5: Low | K5: Local SMB, dental, modelmaking | L5: None listed | M5: None | N5: Micro-scale; single operator risk | O5: mabs3d.com; Italian registry (no accounts filed)
A6: Sculpteo (3D Prod group) | B6: Villejuif + Raon-l'Etape, FR | C6: In-house | D6: SLS, MJF, resin, metal; IM via Platex | E6: Yes (account required) | F6: Express 2 d; Economy ~15 d | G6: Mid-premium | H6: Group EUR 17M combined (company, May 2026); Sculpteo alone EUR 8-10M est. | I6: Two ownership disruptions in 18 months (BASF exit, Forward AM insolvency, sale to 3D Prod 7 May 2026) | J6: Medium | K6: EU industrial + designers | L6: ISO 9001 | M6: Low | N6: Post-merger integration risk; US presence diminished | O6: 3D Prod / Sculpteo release 7 May 2026
A7: i.materialise (Materialise) | B7: Leuven, BE | C7: In-house - CLOSED | D7: Was SLS/SLA/MJF/metal consumer channel | E7: n/a | F7: n/a - stopped orders 31 Oct 2025 | G7: Premium | H7: Materialise Manufacturing segment EUR 92.5M FY2025, -13.2% | I7: Segment adjusted EBITDA negative through 2025; group profit carried by Medical | J7: High | K7: Was prosumer; now B2B via OnSite only | L7: ISO 9001, EN 9100, ISO 13485, EASA POA | M7: High (aero); >500k flight parts | N7: Exited prosumer segment - that demand is up for grabs | O7: Materialise Q4 FY2025 release; Fabbaloo Oct 2025
A8: Shapeways (relaunched) | B8: Eindhoven, NL | C8: In-house + creator marketplace | D8: SLS, MJF, resin, metals, lost-wax, FDM (added 2025); 120+ materials | E8: Yes (account) | F8: Material-dependent | G8: Mid | H8: Not disclosed; <EUR 10M assumed (single plant, restart year) | I8: Chapter 7 July 2024; assets bought by Manuevo BV (original founders); Thangs acquired Dec 2024 | J8: Low | K8: Prosumers, creators, SME | L8: None advertised post-relaunch | M8: Negligible | N8: Trust damage from 2024 bankruptcy (customers lost orders); pricing no longer published | O8: TCT Dec 2024; shapeways.com
A9: Craftcloud (All3DP) | B9: Munich, DE | C9: Aggregator (no assets) | D9: FDM, SLS, MJF, resin, metal, CNC via ~180-200 partners | E9: Yes, no login | F9: 2-10 d + shipping, partner-dependent | G9: Budget (arbitrage) | H9: ~EUR 10M turnover, ~30 staff, break-even (Oct 2024 [STALE]); ~EUR 16M 2026 run-rate if 60% growth held | I9: HTGF, Bayern Kapital, HZG-led growth round Oct 2024, amount undisclosed; take rate est. 15-30% | J9: Medium | K9: Prosumers + SMB | L9: None (asset-less) | M9: None | N9: Same part price swings +/-100% between partners within days; inter-partner quality variance; weak recourse on bad parts | O9: Munich Startup / HTGF 1 Oct 2024; Trustpilot ~2,800 reviews
A10: Xometry Europe | B10: Munich, DE | C10: Marketplace | D10: CNC, sheet, 3DP (7 techs), IM (auto-quoted since 2025) | E10: Yes (login, EUR 30 min order) | F10: 3DP from 2-3 d, CNC from 5 d; delivery often 5-15 business d | G10: Mid | H10: International segment USD 112.9M FY2025, +27% (incl. Asia) | I10: International adj. EBITDA -USD 12.5M FY2025; intl gross margin 37.8%; group first positive adj-EBITDA year 2025 | J10: High | K10: Mid-market OEM engineers | L10: ISO 9001 (EU); CMMC L2 / AS9100D / ITAR in US network | M10: US: courts defense. EU: weapons parts prohibited by default in T&Cs | N10: Slipped express deliveries, out-of-spec parts, slow support escalation, pricey vs local shops at quantity | O10: XMTR 10-K FY2025; Q4 release 24 Feb 2026; xometry.eu T&Cs
A11: Fractory | B11: Tallinn EE / Manchester UK | C11: Marketplace | D11: Sheet metal, tube, CNC (no 3DP) | E11: Sheet instant; CNC hybrid RFQ | F11: Days | G11: Mid | H11: USD 16.1M 2022 (CB Insights [STALE]); GMV est. EUR 25-40M 2025 | I11: ~USD 18.5M raised; SmartCap top-up Apr 2025; Series B in prep; loss-making assumed | J11: Low-Medium | K11: Machinery OEMs, structural steel | L11: Partner-level | M11: Lists A&D as served industry; no export-control infra | N11: No 3DP; expanded FR/IT Mar 2026 | O11: Business Manchester 2 Mar 2026; Machinery Apr 2025
A12: Geomiq | B12: London, UK | C12: Marketplace | D12: CNC, sheet, 3DP, IM via 300+ EU / 1,100+ global partners | E12: Partial instant | F12: Days | G12: Mid | H12: USD 3.8M rev (LeadIQ May 2025, low confidence); GMV plausibly GBP 10-20M | I12: USD 8.5M Series A Jan 2023 [STALE]; ~USD 13.5M total; VC-dependent | J12: Low | K12: UK SMB + enterprise | L12: ISO 9001; partner AS9100/13485 | M12: Some UK defense work | N12: QC complaints on CNC orders (Trustpilot); sales-culture churn (Glassdoor) | O12: geomiq.com; Companies House
... A28: 3DGence services arm | B28: PL | C28: OEM side-business | D28: FDM, SLS, SLA, DMLS, PolyJet | E28: Online quoting funnel | F28: Days | G28: Mid | H28: Side business of printer OEM | I28: - | J28: Low | K28: PL | L28: - | M28: None | N28: Not a core business | O28: 3dgence.com

Sheet Pricing Benchmark
A1: Pricing benchmark: 3 reference parts, July 2026
A2: Part A: PA12 bracket 50x40x30 mm, ~20 cm3 / 25 g, MJF or SLS. Part B: ABS/ASA enclosure 120x80x40 mm, ~75 g, FDM. Part C: 6061/6082 aluminum flange D80x15 mm, CNC.
A3: No live CAD uploads were possible; figures are published prices, provider example quotes and third-party same-STL benchmarks, triangulated. Ranges = ESTIMATE. Chinese prices exclude EUR 10-25 shipping and EU import charges.
A5: Provider | B5: Region | C5: Part A qty 1 | D5: Part A qty 10 (ea) | E5: Part B qty 1 | F5: Part C qty 1 | G5: Part C qty 10 (ea) | H5: Ccy | I5: Min order | J5: Std lead (production) | K5: Quote access | L5: Basis | M5: Key anchor / source
A6: JLC3DP / JLCCNC | B6: CN | C6: 4-8 | D6: 3-6 | E6: 5-10 | F6: 18-35 | G6: 8-14 | H6: USD | I6: None stated | J6: MJF 72 h; CNC days | K6: Instant; account needed to upload | L6: ESTIMATE | M6: PA12-HP 'from $1.00'; ABS 'from $3.00' (jlc3dp.com help, 2025-26); + EUR 3/line EU duty since Jul 2026
A7: PCBWay | B7: CN | C7: 25 (min-order floor) | D7: 4-7 | E7: 25 (min floor) | F7: 25-45 | G7: 8-15 | H7: USD | I7: USD 25 (FACT) | J7: FDM 2-4 d, resin 4-6 d | K7: Instant estimate, manual review before final | L7: FACT floor + EST | M7: pcbway.com FAQ (min order, setup fees USD 5-20)
A8: RapidDirect | B8: CN | C8: 12-22 | D8: 5-9 | E8: 15-30 | F8: 30-60 | G8: 10-18 | H8: USD | I8: No MOQ | J8: 3-5 d ship for protos | K8: Instant + 24 h manual fallback; account | L8: ESTIMATE | M8: rapiddirect.com; own guide cites USD 30-500 SLS/MJF band
A9: Craftcloud | B9: Marketplace | C9: 12-25 + ship | D9: 6-12 | E9: 18-35 + ship | F9: 50-110 | G9: 15-35 | H9: USD | I9: None (FACT) | J9: 1-4 d to 19-23 d, offer-dependent | K9: Instant, NO login needed; CNC often needs 2D drawing | L9: FACT-anchored | M9: All3DP benchmark Jun 2026: SLS nylon enclosure $8.81 + $14 ship; ABS gear $14.71; ASA frame $30.03
A10: Xometry Europe | B10: EU | C10: 18-28 | D10: 9-16 | E10: 25-40 | F10: 60-120 | G10: 18-35 | H10: EUR | I10: EUR 30 (FACT) | J10: MJF/SLS 3 d production | K10: Instant; login required | L10: FACT-anchored [STALE] | M10: Own published refs: MJF PA12 EUR 18.29 q1 / 15.96 ea @20; FDM ABS EUR 22.18 (Dec 2023 page, maintained Oct 2025)
A11: Weerg | B11: EU (IT) | C11: 10-20 | D11: 5-10 | E11: 15-30 | F11: 40-80 | G11: 14-28 | H11: EUR | I11: None; free EU ship >EUR 250 | J11: MJF <2 d production; EU delivery 1-2 d | K11: Instant, NO login | L11: ESTIMATE | M11: weerg.com PA12 + shipping FAQ; positioned below Xometry on MJF
A12: Sculpteo | B12: EU (FR) | C12: 20-35 | D12: 10-18 | E12: 30-50 | F12: n/a (no CNC) | G12: n/a | H12: EUR | I12: Economy tier only when unit >= EUR 10 | J12: Std 2-15 d; Express 2 d (+<=50%) | K12: Instant after free account | L12: FACT tiers + EST | M12: sculpteo.com pricing page (modified Feb 2026)
A13: Shapeways | B13: EU (NL) | C13: 20-35 | D13: 12-20 | E13: n/a | F13: n/a (no CNC) | G13: n/a | H13: USD | I13: Not published | J13: Material-dependent | K13: Instant after account; rate card no longer public | L13: ESTIMATE | M13: Post-relaunch 'optimized MJF/SLS pricing' (Mar 2025); historic ~$1-1.5/cm3
A14: Protolabs | B14: EU/US | C14: 100-150 | D14: 20-40 | E14: 100-150 | F14: 150-300 | G14: 30-60 | H14: USD | I14: No MOQ; ~USD 95 practical floor (FACT) | J14: 1-3 d expedite | K14: Instant; account required | L14: FACT floor + EST | M14: protolabs.com help center; 2024 benchmark: qty-1 MJF part $297 vs Craftcloud $62.65 [STALE]
A15: Hubs / Protolabs Network | B15: EU | C15: 35-60 | D15: 10-20 | E15: 40-70 | F15: 80-150 | G15: 20-40 | H15: USD | I15: Not published | J15: From 3 d | K15: Instant (98% of uploads); account required | L15: ESTIMATE | M15: hubs.com; positioned between Xometry and Protolabs
A17: Where instant quoting failed or required manual RFQ:
A18: - Sculpteo and Shapeways: no CNC offering at all.
A19: - Craftcloud CNC: instant price shown, but partners routinely require a 2D PDF drawing and sales confirmation.
A20: - Facturee, CNC24: no instant quoting - manual RFQ model (hours to days).
A21: - PCBWay: instant price is provisional; final price only after human file review.
A22: - JLC3DP, Xometry, Protolabs, Sculpteo, Shapeways, Hubs: account wall before upload/quote.
A23: - Only Weerg and Craftcloud quote 3DP with no login. Cross-provider spread on identical parts is 4-5x (All3DP same-STL tests, Jun 2026 and Jul 2024).

Sheet Model A FDM Farm
A1: Scenario A: industrial FDM farm, Poland
A2: Blue text on yellow fill = editable assumption. Black = formula. Steady state unless noted.
A4: CAPEX
A5: Machine count | B5: 25 | C5: User scenario: 20-30 units. Test 20 and 30.
A6: Cost per machine incl. spares, EUR | B6: 3000 | C6: ASSUMPTION. Range EUR 1,500 (Bambu H2D class) to EUR 12,000+ (Ultimaker S8 class). Most commercial farms now run prosumer-industrial CoreXY units.
A7: Machines subtotal, EUR | B7: =B5*B6 -> 75000
A8: Facility fit-out (racks, ventilation, electrical), EUR | B8: 40000 | C8: ASSUMPTION for ~300 m2 leased space in PL.
A9: Quoting engine + website build, EUR | B9: 60000 | C9: ASSUMPTION. Instant-quote engine is the core product; in-house build with off-the-shelf slicer APIs.
A10: Contingency, % of above | B10: 0.1
A11: Total CAPEX, EUR | B11: =(B7+B8+B9)*(1+B10) -> 192500
A13: Operating assumptions
A14: Utilization (printing share of 8,760 h/yr) | B14: 0.5 | C14: ASSUMPTION. 50% = ~12 h/day effective. Well-run farms reach 60%+; ramp-up years run lower.
A15: Realized revenue per machine-hour, EUR | B15: 4 | C15: ESTIMATE. At ~20 g/h this is ~EUR 0.20/g - between JLC3DP (~USD 0.03-0.08/g) and Xometry EU (~EUR 0.30+/g). Key lever - test 3.00-6.00.
A16: Material throughput, g/h | B16: 20 | C16: ASSUMPTION. 0.6 mm nozzle functional parts; 15-30 g/h typical.
A17: Material cost, EUR/kg | B17: 20 | C17: FACT-range. ASA/PETG/PA-CF blended spool cost at volume.
A18: Operator FTE | B18: 2 | C18: Loading, depowdering n/a, finishing, packing.
A19: Engineer / admin FTE | B19: 1
A20: Cost per operator FTE, EUR/yr | B20: 35000 | C20: FACT-anchored: PL manufacturing labour cost EUR 17.10/h (Eurostat 2025) x ~2,000 h.
A21: Cost per engineer FTE, EUR/yr | B21: 55000
A22: Avg machine power draw, kW | B22: 0.35
A23: Electricity price, EUR/kWh | B23: 0.18 | C23: PL industrial tariff, ASSUMPTION.
A24: Rent + utilities, EUR/yr | B24: 20000 | C24: ~300 m2 at ~EUR 5/m2/month, PL regional city.
A25: Net shipping cost, % of revenue | B25: 0.03 | C25: Most shipping billed to customer; net subsidy for free-shipping threshold.
A26: Marketing + payment fees, % of revenue | B26: 0.1 | C26: Launch-phase level. SendCutSend playbook is content-led; can fall to ~5% at scale.
A27: Other overhead (SaaS, insurance, accounting), EUR/yr | B27: 20000
A28: Year-1 demand ramp (share of steady-state revenue) | B28: 0.5
A30: Steady-state P&L
A31: Machine-hours sold / yr | B31: =B5*8760*B14 -> 109500
A32: Revenue, EUR | B32: =B31*B15 -> 438000
A33: Materials | B33: =B31*B16*B17/1000 -> 43800
A34: Labor | B34: =B18*B20+B19*B21 -> 125000
A35: Energy | B35: =B31*B22*B23 -> 6898.5
A36: Rent + utilities | B36: =B24 -> 20000
A37: Net shipping | B37: =B32*B25 -> 13140
A38: Marketing + payment fees | B38: =B32*B26 -> 43800
A39: Other overhead | B39: =B27 -> 20000
A40: Total operating cost | B40: =SUM(B33:B39) -> 272638.5
A41: EBITDA, EUR | B41: =B32-B40 -> 165361.5
A42: EBITDA margin | B42: =IFERROR(B41/B32,0) -> 0.37753767 | C42: Compare: Weerg reports ~40% (company claim, Feb 2026).
A44: Year 1 and payback
...

Sheet Model B MJF Cell
A1: Scenario B: single MJF cell (HP Jet Fusion 5600-class), Poland
A2: Blue text on yellow fill = editable assumption. Black = formula. A Formlabs Fuse SLS cell (~USD 57k complete) is the low-CAPEX alternative; see note row 51.
A4: CAPEX
A5: Printer + processing station, EUR | B5: 500000 | C5: ESTIMATE. HP MJF 5000-series from ~USD 350k; 5200/5400/5600 series to USD 600k+ (mastergraphics.com dealer blog). Weerg runs 28-30x HP 5620.
A6: Ancillaries (bead blasting, dyeing, compressor), EUR | B6: 60000
A7: Facility fit-out, EUR | B7: 40000
A8: Contingency, % of above | B8: 0.1
A9: Total CAPEX, EUR | B9: =(B5+B6+B7)*(1+B8) -> 660000
A11: Operating assumptions
A12: Build chamber volume, liters | B12: 41 | C12: FACT: 380 x 284 x 380 mm chamber.
A13: Packing density | B13: 0.11 | C13: ASSUMPTION. 8-12% typical for mixed job-shop builds.
A14: Builds per week | B14: 6 | C14: ASSUMPTION. ~1/working day with fast-cooling processing station; 10+ possible with extra build units.
A15: Production weeks / yr | B15: 50
A16: Realized price, EUR/cm3 | B16: 0.4 | C16: ESTIMATE. JLC3DP effective ~EUR 0.10-0.15/cm3; Xometry EU small parts ~EUR 0.90; Weerg-competitive ~EUR 0.30-0.50. Key lever.
A17: PA12 powder price, EUR/kg | B17: 55
A18: Effective powder factor (refresh + waste) | B18: 1.5 | C18: ASSUMPTION. 80% reuse ratio implies ~1.4-1.6x part weight in fresh powder.
A19: Part density, g/cm3 | B19: 1.01 | C19: FACT for MJF PA12.
A20: Agents + consumables, EUR/cm3 | B20: 0.03
A21: Operator FTE | B21: 1.5
A22: Cost per FTE, EUR/yr | B22: 40000
A23: Energy, EUR/yr | B23: 12000 | C23: Printer + station + compressor, ASSUMPTION.
A24: Rent + utilities, EUR/yr | B24: 12000
A25: Net shipping, % of revenue | B25: 0.03
A26: Marketing + payment fees, % of revenue | B26: 0.1
A27: Other overhead, EUR/yr | B27: 15000
A28: Year-1 demand ramp | B28: 0.5
A30: Steady-state P&L
A31: Sellable volume, cm3/yr | B31: =B12*1000*B13*B14*B15 -> 1353000
A32: Revenue, EUR | B32: =B31*B16 -> 541200
A33: Powder | B33: =B31*B19/1000*B17*B18 -> 112738.73
A34: Agents + consumables | B34: =B31*B20 -> 40590
A35: Labor | B35: =B21*B22 -> 60000
A36: Energy | B36: =B23 -> 12000
A37: Rent + utilities | B37: =B24 -> 12000
A38: Net shipping | B38: =B32*B25 -> 16236
A39: Marketing + payment fees | B39: =B32*B26 -> 54120
A40: Other overhead | B40: =B27 -> 15000
A41: Total operating cost | B41: =SUM(B33:B40) -> 322684.72
A42: EBITDA, EUR | B42: =B32-B41 -> 218515.27
A43: EBITDA margin | B43: =IFERROR(B42/B32,0) -> 0.40376067
...

Sheet Scenario Compare
A1: Entry scenarios side by side
A2: Green = pulled live from the model tabs. Change assumptions there; this updates.
A4: Metric | B4: A: FDM farm (25 units) | C4: B: MJF cell (1x HP 5600-class)
A5: Total CAPEX, EUR | B5: ='Model A FDM Farm'!B11 -> 192500 | C5: ='Model B MJF Cell'!B9 -> 660000
A6: Steady-state revenue, EUR | B6: ='Model A FDM Farm'!B32 -> 438000 | C6: ='Model B MJF Cell'!B32 -> 541200
A7: Steady-state EBITDA, EUR | B7: ='Model A FDM Farm'!B41 -> 165361.5 | C7: ='Model B MJF Cell'!B42 -> 218515.27
A8: EBITDA margin | B8: ='Model A FDM Farm'!B42 -> 0.37753767 | C8: ='Model B MJF Cell'!B43 -> 0.40376067
A9: Payback incl. Year-1 ramp, years | B9: ='Model A FDM Farm'!B48 -> 2.1630231 | C9: ='Model B MJF Cell'!B49 -> 3.7469126
A10: Revenue per EUR CAPEX | B10: =IFERROR('Model A FDM Farm'!B32/'Model A FDM Farm'!B11,0) -> 2.2753247 | C10: =IFERROR('Model B MJF Cell'!B32/'Model B MJF Cell'!B9,0) -> 0.82
A12: - Read: the FDM farm is the capital-efficient wedge (low CAPEX, ~1-2 yr payback) but sits in the segment most exposed to desktop-printer cannibalization and JLC3DP pricing.
A13: - The MJF cell carries ~3.5x the CAPEX and a longer payback at single-machine utilization, but produces the industrial PA12 parts that desktop printers cannot, at Weerg-class margins once utilization is high.
A14: - Weerg anchor: ~EUR 18M revenue, ~40% EBITDA, 2.5M parts/yr on 28-30 MJF machines (Industria Italiana, Feb 2026). Its economics come from fleet scale and uniform machines, not from any single cell.
